<?xml version="1.0"?>
<robot xmlns:sensor="http://playerstage.sourceforge.net/gazebo/xmlschema/#sensor"
       xmlns:controller="http://playerstage.sourceforge.net/gazebo/xmlschema/#controller"
       xmlns:interface="http://playerstage.sourceforge.net/gazebo/xmlschema/#interface"
       xmlns:xacro="http://playerstage.sourceforge.net/gazebo/xmlschema/#interface"
       name="rocketbox_male" >

  <material name="Blue">
    <color rgba="0.0 0.0 0.8 1.0"/>
  </material>
  <material name="Green">
    <color rgba="0.0 0.8 0.0 1.0"/>
  </material>
  <material name="Grey">
    <color rgba="0.7 0.7 0.7 1.0"/>
  </material>
  <material name="Grey2">
    <color rgba="0.9 0.9 0.9 1.0"/>
  </material>
  <material name="Red">
    <color rgba="0.8 0.0 0.0 1.0"/>
  </material>
  <material name="White">
    <color rgba="1.0 1.0 1.0 1.0"/>
  </material>
  <material name="Black">
    <color rgba="0.1 0.1 0.1 1.0"/>
  </material>
  <material name="LightGrey">
    <color rgba="0.6 0.6 0.6 1.0"/>
  </material>

  <link name="root_link"/>
  <link name="base_prismatic_dummy1">
    <visual>
      <origin rpy="0 0 0" xyz="0 0 0"/>
      <geometry>
        <box size="0.001 0.001 0.001"/>
      </geometry>
      <material name="Blue"/>
    </visual>
  </link>
  <link name="base_prismatic_dummy2">
    <visual>
      <origin rpy="0 0 0" xyz="0 0 0"/>
      <geometry>
        <box size="0.001 0.001 0.001"/>
      </geometry>
      <material name="Blue"/>
    </visual>
  </link>
  <link name="base_prismatic_dummy3">
    <visual>
      <origin rpy="0 0 0" xyz="0 0 0"/>
      <geometry>
        <box size="0.001 0.001 0.001"/>
      </geometry>
      <material name="Blue"/>
    </visual>
  </link>
  <link name="base_revolute_dummy1">
    <visual>
      <origin rpy="0 0 0" xyz="0 0 0"/>
      <geometry>
        <box size="0.001 0.001 0.001"/>
      </geometry>
      <material name="Blue"/>
    </visual>
  </link>
  <link name="base_revolute_dummy2">
    <visual>
      <origin rpy="0 0 0" xyz="0 0 0"/>
      <geometry>
        <box size="0.001 0.001 0.001"/>
      </geometry>
      <material name="Blue"/>
    </visual>
  </link>
  <joint name="base_prismatic_joint_x" type="prismatic">
    <axis xyz="1 0 0"/>
    <limit effort="10000" lower="-5.0" upper="5.0" velocity="0.6"/>
    <safety_controller k_position="100" k_velocity="2000000" soft_lower_limit="-4.9" soft_upper_limit="4.9"/>
    <calibration falling="0.00536"/>
    <dynamics damping="20000.0"/>
    <origin rpy="0 0 0" xyz="0 0 0"/>
    <parent link="root_link"/>
    <child link="base_prismatic_dummy1"/>
  </joint>
  <joint name="base_prismatic_joint_y" type="prismatic">
    <axis xyz="0 1 0"/>
    <limit effort="10000" lower="-5.0" upper="5.0" velocity="0.6"/>
    <safety_controller k_position="100" k_velocity="2000000" soft_lower_limit="-4.9" soft_upper_limit="4.9"/>
    <calibration falling="0.00536"/>
    <dynamics damping="20000.0"/>
    <origin rpy="0 0 0" xyz="0 0 0"/>
    <parent link="base_prismatic_dummy1"/>
    <child link="base_prismatic_dummy2"/>
  </joint>
  <joint name="base_prismatic_joint_z" type="prismatic">
    <axis xyz="0 0 1"/>
    <limit effort="10000" lower="-10.0" upper="10.0" velocity="0.6"/>
    <safety_controller k_position="100" k_velocity="2000000" soft_lower_limit="-10.0" soft_upper_limit="10.0"/>
    <calibration falling="0.00536"/>
    <dynamics damping="20000.0"/>
    <origin rpy="0 0 0" xyz="0 0 0"/>
    <parent link="base_prismatic_dummy2"/>
    <child link="base_prismatic_dummy3"/>
  </joint>
  <joint name="base_revolute_joint_x" type="continuous">
    <axis xyz="1 0 0"/>
    <origin rpy="0 0 0" xyz="0 0 0"/>
    <parent link="base_prismatic_dummy3"/>
    <child link="base_revolute_dummy1"/>
  </joint>
  <joint name="base_revolute_joint_y" type="continuous">
    <axis xyz="0 1 0"/>
    <origin rpy="0 0 0" xyz="0 0 0"/>
    <parent link="base_revolute_dummy1"/>
    <child link="base_revolute_dummy2"/>
  </joint>
  <joint name="base_revolute_joint_z" type="continuous">
    <axis xyz="0 0 1"/>
    <origin rpy="0 0 0" xyz="0 0 0"/>
    <parent link="base_revolute_dummy2"/>
    <child link="pelvis_link"/>
  </joint>  
  <link name="pelvis_link">
    <inertial>
      <mass value="24.9873014159"/>
      <inertia ixx="0.219399825" ixy="0.000000009184695" ixz="0.000000062599005" iyy="0.21939959375" iyz="-0.000000006475555" izz="0.22992248625"/>
      <origin xyz="0 -0.00000001 0.0983925"/>
    </inertial>
  </link>	  
  <joint name="torso_z_joint" type="revolute">
    <axis xyz="0 0 1"/>
    <limit effort="15" lower="-0.7" upper="0.7" velocity="5"/>
    <origin rpy="0 0 0" xyz="0 0 0"/>
    <parent link="pelvis_link"/>
    <child link="torso_z_link"/>
  </joint>
  <joint name="torso_y_joint" type="revolute">
    <axis xyz="0 1 0"/>
    <limit effort="15" lower="-0.3" upper="0.3" velocity="5"/>
    <origin rpy="0 0 0" xyz="0 0 0"/>
    <parent link="torso_z_link"/>
    <child link="torso_y_link"/>
  </joint>
  <joint name="torso_x_joint" type="revolute">
    <axis xyz="1 0 0"/>
    <limit effort="15" lower="-1.0" upper="0" velocity="5"/>
    <origin rpy="0 0 0" xyz="0 0 0"/>
    <parent link="torso_y_link"/>
    <child link="torso_x_link"/>
  </joint>  

  <link name="torso_z_link"/>
  <link name="torso_y_link"/>
  <link name="torso_x_link">
    <visual>
      <origin rpy="0 0 0" xyz="0 0 0"/>
      <geometry>
        <mesh filename="../spider/model/mesh/Root.obj"/>
      </geometry>
      <material name="Blue"/>
    </visual>
    <collision>
      <origin rpy="0 0 0" xyz="0 0 0"/>
      <geometry>
        <mesh filename="../spider/model/mesh/Root.obj"/>
      </geometry>
    </collision>
    <inertial>
      <mass value="54.1902903318"/>
      <inertia ixx="1.0895931125" ixy="0.000001152997515" ixz="-0.000000460619845" iyy="1.4490895525" iyz="0.000000968452985" izz="0.679463005"/>
      <origin xyz="0 -0.00000025 0.22608234"/>
    </inertial>
  </link>  
  
  <joint name="head_joint" type="revolute">
    <axis xyz="0 0 1"/>
    <limit effort="15" lower="-1.2" upper="1.2" velocity="5"/>
    <origin rpy="0 0 0" xyz="0 0.4982 0"/>
    <parent link="torso_x_link"/>
    <child link="head_link"/>
  </joint>

  <link name="head_link"/>

   <joint name="middleleftshoulder_joint" type="revolute">
    <axis xyz="0 0 1"/>
    <limit effort="15" lower="-1.57" upper="1" velocity="5"/>

    <origin rpy="0 0 0" xyz="0 0 0"/>
    <parent link="head_link"/>
    <child link="middleleftshoulder_link"/>
  </joint>

  <link name="middleleftshoulder_link"/>
  
  <joint name="MiddleLeftUpperLimb_z_joint" type="revolute">
    <axis xyz="0 0 1"/>
    <limit effort="15" lower="-1.57" upper="1" velocity="5"/>

    <origin rpy="0 0 0" xyz="-0.1891 0 -0.0795"/>
    <parent link="middleleftshoulder_link"/>
    <child link="MiddleLeftUpperLimb_z_link"/>
  </joint>
  <joint name="MiddleLeftUpperLimb_y_joint" type="revolute">
    <axis xyz="0 1 0"/>
    <limit effort="15" lower="-1.57" upper="0.7" velocity="5"/>
    <origin rpy="0 0 0" xyz="0 0 0"/>
    <parent link="MiddleLeftUpperLimb_z_link"/>
    <child link="MiddleLeftUpperLimb_y_link"/>
  </joint>
  <joint name="MiddleLeftUpperLimb_x_joint" type="revolute">
    <axis xyz="1 0 0"/>
    <limit effort="15" lower="-1.2" upper="1.57" velocity="5"/>
    <origin rpy="0 0 0" xyz="0 0 0"/>
    <parent link="MiddleLeftUpperLimb_y_link"/>
    <child link="MiddleLeftUpperLimb_x_link"/>
  </joint>

  <link name="MiddleLeftUpperLimb_z_link"/>
  <link name="MiddleLeftUpperLimb_y_link"/>
  <link name="MiddleLeftUpperLimb_x_link">
    <visual>
      <origin rpy="0 0 0" xyz="0 0 0"/>
      <geometry>
        <mesh filename="../spider/model/mesh/MiddleLeftUpperLimb.obj"/>
      </geometry>
      <material name="Blue"/>
    </visual>
    <collision>
      <origin rpy="0 0 0" xyz="0 0 0"/>
      <geometry>
        <mesh filename="../spider/model/mesh/MiddleLeftUpperLimb.obj"/>
      </geometry>
    </collision>
    <inertial>
      <mass value="11.28066677275"/>
      <inertia ixx="0.258606759375" ixy="0.000002463301455" ixz="0.00032211891975" iyy="0.258311314375" iyz="-0.000065609605275" izz="0.021073428046875"/>
      <origin xyz="-0.00364974 -0.00003172 -0.19576731"/>
    </inertial>
  </link>

  <joint name="MiddleLeftLimb_joint" type="revolute">
    <axis xyz="0 1 0"/>
    <limit effort="15" lower="-2.4" upper="0" velocity="5"/>
    <origin rpy="0 0 0" xyz="-0.4456 0.0015 0.1781"/>
    <parent link="MiddleLeftUpperLimb_x_link"/>
    <child link="MiddleLeftLimb_link"/>
  </joint>

  <link name="MiddleLeftLimb_link">
    <visual>
      <origin rpy="0 0 0" xyz="0 0 0"/>
      <geometry>
        <mesh filename="../spider/model/mesh/MiddleLeftLimb.obj"/>
      </geometry>
      <material name="Blue"/>
    </visual>
    <collision>
      <origin rpy="0 0 0" xyz="0 0 0"/>
      <geometry>
        <mesh filename="../spider/model/mesh/MiddleLeftLimb.obj"/>
      </geometry>
    </collision>
    <inertial>
      <mass value="8.394054321"/>
      <inertia ixx="0.1879741409375" ixy="0.000000001719205" ixz="-0.00000000509231" iyy="0.1879741525" iyz="-0.00000001780773" izz="0.01166299402353"/>
      <origin xyz="0.0 -0.00029422 -0.20195734"/>
    </inertial>
  </link>

  <joint name="MiddleLeftLowerLimb_joint" type="revolute">
    <axis xyz="0 1 0"/>
    <limit effort="15" lower="-2.4" upper="0" velocity="5"/>
    <origin rpy="0 0 0" xyz="-0.3928 -0.0167 -0.3044"/>
    <parent link="MiddleLeftLimb_link"/>
    <child link="MiddleLeftLowerLimb_link"/>
  </joint>

  <link name="MiddleLeftLowerLimb_link">
    <visual>
      <origin rpy="0 0 0" xyz="0 0 0"/>
      <geometry>
        <mesh filename="../spider/model/mesh/MiddleLeftLowerLimb.obj"/>
      </geometry>
      <material name="Blue"/>
    </visual>
    <collision>
      <origin rpy="0 0 0" xyz="0 0 0"/>
      <geometry>
        <mesh filename="../spider/model/mesh/MiddleLeftLowerLimb.obj"/>
      </geometry>
    </collision>
    <inertial>
      <mass value="8.394054321"/>
      <inertia ixx="0.1879741409375" ixy="0.000000001719205" ixz="-0.00000000509231" iyy="0.1879741525" iyz="-0.00000001780773" izz="0.01166299402353"/>
      <origin xyz="0.0 -0.00029422 -0.20195734"/>
    </inertial>
  </link>


  <joint name="MiddleLeftEffector_z_joint" type="revolute">
    <axis xyz="0 0 1"/>
    <limit effort="15" lower="-0.01" upper="0" velocity="5"/>
    <origin rpy="0 0 0" xyz="-0.4343 -0.054 -0.1597"/>
    <parent link="MiddleLeftLowerLimb_link"/>
    <child link="MiddleLeftEffector_z_link"/>
  </joint>
  <joint name="MiddleLeftEffector_y_joint" type="revolute">
    <axis xyz="0 1 0"/>
    <limit effort="15" lower="-0.5" upper="0.5" velocity="5"/>
    <origin rpy="0 0 0" xyz="0 0 0"/>
    <parent link="MiddleLeftEffector_z_link"/>
    <child link="MiddleLeftEffector_y_link"/>
  </joint>
  <joint name="MiddleLeftEffector_x_joint" type="revolute">
    <axis xyz="1 0 0"/>
    <limit effort="15" lower="-0.8" upper="0.6" velocity="5"/>
    <origin rpy="0 0 0" xyz="0 0 0"/>
    <parent link="MiddleLeftEffector_y_link"/>
    <child link="MiddleLeftEffector_x_link"/>
  </joint>

  <link name="MiddleLeftEffector_z_link"/>
  <link name="MiddleLeftEffector_y_link"/>
  <link name="MiddleLeftEffector_x_link">
    <visual>
      <origin rpy="0 0 0" xyz="0 0 0"/>
      <geometry>
        <mesh filename="../spider/model/mesh/MiddleLeftEffector.obj"/>
      </geometry>
      <material name="Blue"/>
    </visual>
    <collision>
      <origin rpy="0 0 0" xyz="0 0 0"/>
      <geometry>
        <mesh filename="../spider/model/mesh/MiddleLeftEffector.obj"/>
      </geometry>
    </collision>
    <inertial>
      <mass value="2.24629475115"/>
      <inertia ixx="0.00997119431636" ixy="-0.00032381616821" ixz="0.00003556416949" iyy="0.00325251065432" iyz="0.00137797584221" izz="0.01040399675772"/>
      <origin xyz="-0.00160579 0.04884521 -0.0783361"/>
    </inertial>
  </link>
	
	  
  <joint name="Middleleft_foot_endeffector_joint" type="fixed">
    <axis xyz="0 0 1"/>
    <limit effort="15" lower="-0.001" upper="0.001" velocity="5"/>
    <origin rpy="0 0 0" xyz="-0.024924 -0.097428 0.001788"/>
    <parent link="MiddleLeftEffector_x_link"/>
    <child link="Middleleft_foot_endeffector_link"/>
  </joint>

  <link name="Middleleft_foot_endeffector_link">
    <visual>
      <origin rpy="0 0 0" xyz="0 0 0"/>
      <geometry>
        <box size="0.001 0.001 0.001"/>
      </geometry>
      <material name="Blue"/>
    </visual>
  </link>  
  
<link name="Middleleft_foot_cp_1_link">
    <visual>
      <origin rpy="0 0 0" xyz="0 0 0"/>
      <geometry>
        <box size="0.001 0.001 0.001"/>
      </geometry>
      <material name="Blue"/>
    </visual>
    <inertial>
      <mass value="0"/>
      <inertia ixx="1" ixy="0" ixz="0" iyy="1" iyz="0" izz="0"/>
      <origin xyz="0 0 0"/>
    </inertial>
  </link>
  <link name="Middleleft_foot_cp_2_link">
    <visual>
      <origin rpy="0 0 0" xyz="0 0 0"/>
      <geometry>
        <box size="0.001 0.001 0.001"/>
      </geometry>
      <material name="Blue"/>
    </visual>
    <inertial>
      <mass value="0"/>
      <inertia ixx="1" ixy="0" ixz="0" iyy="1" iyz="0" izz="0"/>
      <origin xyz="0 0 0"/>
    </inertial>
  </link>
  <link name="Middleleft_foot_cp_3_link">
    <visual>
      <origin rpy="0 0 0" xyz="0 0 0"/>
      <geometry>
        <box size="0.001 0.001 0.001"/>
      </geometry>
      <material name="Blue"/>
    </visual>
    <inertial>
      <mass value="0"/>
      <inertia ixx="1" ixy="0" ixz="0" iyy="1" iyz="0" izz="0"/>
      <origin xyz="0 0 0"/>
    </inertial>
  </link>
  <link name="Middleleft_foot_cp_4_link">
    <visual>
      <origin rpy="0 0 0" xyz="0 0 0"/>
      <geometry>
        <box size="0.001 0.001 0.001"/>
      </geometry>
      <material name="Blue"/>
    </visual>
    <inertial>
      <mass value="0"/>
      <inertia ixx="1" ixy="0" ixz="0" iyy="1" iyz="0" izz="0"/>
      <origin xyz="0 0 0"/>
    </inertial>
  </link>
  <joint name="Middleleft_foot_cp_1_joint" type="revolute">
    <axis xyz="0 0 1"/>
    <limit effort="15" lower="0" upper="0" velocity="5"/>
    <origin rpy="0 0 0" xyz="-0.05 0.02 -0.005"/>
    <parent link="MiddleLeftEffector_x_link"/>
    <child link="Middleleft_foot_cp_1_link"/>
  </joint>
  <joint name="Middleleft_foot_cp_2_joint" type="revolute">
    <axis xyz="0 0 1"/>
    <limit effort="15" lower="0" upper="0" velocity="5"/>
    <origin rpy="0 0 0" xyz="-0.12 0.02 -0.005"/>
    <parent link="MiddleLeftEffector_x_link"/>
    <child link="Middleleft_foot_cp_2_link"/>
  </joint>
  <joint name="Middleleft_foot_cp_3_joint" type="revolute">
    <axis xyz="0 0 1"/>
    <limit effort="15" lower="0" upper="0" velocity="5"/>
    <origin rpy="0 0 0" xyz="-0.09166 -0.07769 -0.12195"/>
    <parent link="MiddleLeftEffector_x_link"/>
    <child link="Middleleft_foot_cp_3_link"/>
  </joint>
  <joint name="Middleleft_foot_cp_4_joint" type="revolute">
    <axis xyz="0 0 1"/>
    <limit effort="15" lower="0" upper="0" velocity="5"/>
    <origin rpy="0 0 0" xyz="-0.05 -0.08 -0.005"/>
    <parent link="MiddleLeftEffector_x_link"/>
    <child link="Middleleft_foot_cp_4_link"/>
  </joint>

   <joint name="frontleftshoulder_joint" type="revolute">
    <axis xyz="0 0 1"/>
    <limit effort="15" lower="-1.57" upper="1" velocity="5"/>

    <origin rpy="0 0 0" xyz="0 0 0"/>
    <parent link="head_link"/>
    <child link="frontleftshoulder_link"/>
  </joint>

  <link name="frontleftshoulder_link"/>
  
  <joint name="FrontLeftUpperLimb_z_joint" type="revolute">
    <axis xyz="0 0 1"/>
    <limit effort="15" lower="-1.57" upper="1" velocity="5"/>

    <origin rpy="0 0 0" xyz="-0.1891 0 -0.0795"/>
    <parent link="frontleftshoulder_link"/>
    <child link="FrontLeftUpperLimb_z_link"/>
  </joint>
  <joint name="FrontLeftUpperLimb_y_joint" type="revolute">
    <axis xyz="0 1 0"/>
    <limit effort="15" lower="-1.57" upper="0.7" velocity="5"/>
    <origin rpy="0 0 0" xyz="0 0 0"/>
    <parent link="FrontLeftUpperLimb_z_link"/>
    <child link="FrontLeftUpperLimb_y_link"/>
  </joint>
  <joint name="FrontLeftUpperLimb_x_joint" type="revolute">
    <axis xyz="1 0 0"/>
    <limit effort="15" lower="-1.2" upper="1.57" velocity="5"/>
    <origin rpy="0 0 0" xyz="0 0 0"/>
    <parent link="FrontLeftUpperLimb_y_link"/>
    <child link="FrontLeftUpperLimb_x_link"/>
  </joint>

  <link name="FrontLeftUpperLimb_z_link"/>
  <link name="FrontLeftUpperLimb_y_link"/>
  <link name="FrontLeftUpperLimb_x_link">
    <visual>
      <origin rpy="0 0 0" xyz="0 0 0"/>
      <geometry>
        <mesh filename="../spider/model/mesh/MiddleLeftUpperLimb.obj"/>
      </geometry>
      <material name="Blue"/>
    </visual>
    <collision>
      <origin rpy="0 0 0" xyz="0 0 0"/>
      <geometry>
        <mesh filename="../spider/model/mesh/MiddleLeftUpperLimb.obj"/>
      </geometry>
    </collision>
    <inertial>
      <mass value="11.28066677275"/>
      <inertia ixx="0.258606759375" ixy="0.000002463301455" ixz="0.00032211891975" iyy="0.258311314375" iyz="-0.000065609605275" izz="0.021073428046875"/>
      <origin xyz="-0.00364974 -0.00003172 -0.19576731"/>
    </inertial>
  </link>

  <joint name="FrontLeftLimb_joint" type="revolute">
    <axis xyz="0 1 0"/>
    <limit effort="15" lower="-2.4" upper="0" velocity="5"/>
    <origin rpy="0 0 0" xyz="-0.4456 0.0015 0.1781"/>
    <parent link="FrontLeftUpperLimb_x_link"/>
    <child link="FrontLeftLimb_link"/>
  </joint>

  <link name="FrontLeftLimb_link">
    <visual>
      <origin rpy="0 0 0" xyz="0 0 0"/>
      <geometry>
        <mesh filename="../spider/model/mesh/MiddleLeftLimb.obj"/>
      </geometry>
      <material name="Blue"/>
    </visual>
    <collision>
      <origin rpy="0 0 0" xyz="0 0 0"/>
      <geometry>
        <mesh filename="../spider/model/mesh/MiddleLeftLimb.obj"/>
      </geometry>
    </collision>
    <inertial>
      <mass value="8.394054321"/>
      <inertia ixx="0.1879741409375" ixy="0.000000001719205" ixz="-0.00000000509231" iyy="0.1879741525" iyz="-0.00000001780773" izz="0.01166299402353"/>
      <origin xyz="0.0 -0.00029422 -0.20195734"/>
    </inertial>
  </link>

  <joint name="FrontLeftLowerLimb_joint" type="revolute">
    <axis xyz="0 1 0"/>
    <limit effort="15" lower="-2.4" upper="0" velocity="5"/>
    <origin rpy="0 0 0" xyz="-0.3928 -0.0167 -0.3044"/>
    <parent link="FrontLeftLimb_link"/>
    <child link="FrontLeftLowerLimb_link"/>
  </joint>

  <link name="FrontLeftLowerLimb_link">
    <visual>
      <origin rpy="0 0 0" xyz="0 0 0"/>
      <geometry>
        <mesh filename="../spider/model/mesh/MiddleLeftLowerLimb.obj"/>
      </geometry>
      <material name="Blue"/>
    </visual>
    <collision>
      <origin rpy="0 0 0" xyz="0 0 0"/>
      <geometry>
        <mesh filename="../spider/model/mesh/MiddleLeftLowerLimb.obj"/>
      </geometry>
    </collision>
    <inertial>
      <mass value="8.394054321"/>
      <inertia ixx="0.1879741409375" ixy="0.000000001719205" ixz="-0.00000000509231" iyy="0.1879741525" iyz="-0.00000001780773" izz="0.01166299402353"/>
      <origin xyz="0.0 -0.00029422 -0.20195734"/>
    </inertial>
  </link>


  <joint name="FrontLeftEffector_z_joint" type="revolute">
    <axis xyz="0 0 1"/>
    <limit effort="15" lower="-0.01" upper="0" velocity="5"/>
    <origin rpy="0 0 0" xyz="-0.4343 -0.054 -0.1597"/>
    <parent link="FrontLeftLowerLimb_link"/>
    <child link="FrontLeftEffector_z_link"/>
  </joint>
  <joint name="FrontLeftEffector_y_joint" type="revolute">
    <axis xyz="0 1 0"/>
    <limit effort="15" lower="-0.5" upper="0.5" velocity="5"/>
    <origin rpy="0 0 0" xyz="0 0 0"/>
    <parent link="FrontLeftEffector_z_link"/>
    <child link="FrontLeftEffector_y_link"/>
  </joint>
  <joint name="FrontLeftEffector_x_joint" type="revolute">
    <axis xyz="1 0 0"/>
    <limit effort="15" lower="-0.8" upper="0.6" velocity="5"/>
    <origin rpy="0 0 0" xyz="0 0 0"/>
    <parent link="FrontLeftEffector_y_link"/>
    <child link="FrontLeftEffector_x_link"/>
  </joint>

  <link name="FrontLeftEffector_z_link"/>
  <link name="FrontLeftEffector_y_link"/>
  <link name="FrontLeftEffector_x_link">
    <visual>
      <origin rpy="0 0 0" xyz="0 0 0"/>
      <geometry>
        <mesh filename="../spider/model/mesh/MiddleLeftEffector.obj"/>
      </geometry>
      <material name="Blue"/>
    </visual>
    <collision>
      <origin rpy="0 0 0" xyz="0 0 0"/>
      <geometry>
        <mesh filename="../spider/model/mesh/MiddleLeftEffector.obj"/>
      </geometry>
    </collision>
    <inertial>
      <mass value="2.24629475115"/>
      <inertia ixx="0.00997119431636" ixy="-0.00032381616821" ixz="0.00003556416949" iyy="0.00325251065432" iyz="0.00137797584221" izz="0.01040399675772"/>
      <origin xyz="-0.00160579 0.04884521 -0.0783361"/>
    </inertial>
  </link>
	
	  
  <joint name="Frontleft_foot_endeffector_joint" type="revolute">
    <axis xyz="0 0 1"/>
    <limit effort="15" lower="-0.001" upper="0.001" velocity="5"/>
    <origin rpy="0 0 0" xyz="-0.1086 -0.0059 -0.0138"/>
    <parent link="FrontLeftEffector_x_link"/>
    <child link="Frontleft_foot_endeffector_link"/>
  </joint>

  <link name="Frontleft_foot_endeffector_link">
    <visual>
      <origin rpy="0 0 0" xyz="0 0 0"/>
      <geometry>
        <box size="0.001 0.001 0.001"/>
      </geometry>
      <material name="Blue"/>
    </visual>
  </link>  
  
<link name="Frontleft_foot_cp_1_link">
    <visual>
      <origin rpy="0 0 0" xyz="0 0 0"/>
      <geometry>
        <box size="0.001 0.001 0.001"/>
      </geometry>
      <material name="Blue"/>
    </visual>
    <inertial>
      <mass value="0"/>
      <inertia ixx="1" ixy="0" ixz="0" iyy="1" iyz="0" izz="0"/>
      <origin xyz="0 0 0"/>
    </inertial>
  </link>
  <link name="Frontleft_foot_cp_2_link">
    <visual>
      <origin rpy="0 0 0" xyz="0 0 0"/>
      <geometry>
        <box size="0.001 0.001 0.001"/>
      </geometry>
      <material name="Blue"/>
    </visual>
    <inertial>
      <mass value="0"/>
      <inertia ixx="1" ixy="0" ixz="0" iyy="1" iyz="0" izz="0"/>
      <origin xyz="0 0 0"/>
    </inertial>
  </link>
  <link name="Frontleft_foot_cp_3_link">
    <visual>
      <origin rpy="0 0 0" xyz="0 0 0"/>
      <geometry>
        <box size="0.001 0.001 0.001"/>
      </geometry>
      <material name="Blue"/>
    </visual>
    <inertial>
      <mass value="0"/>
      <inertia ixx="1" ixy="0" ixz="0" iyy="1" iyz="0" izz="0"/>
      <origin xyz="0 0 0"/>
    </inertial>
  </link>
  <link name="Frontleft_foot_cp_4_link">
    <visual>
      <origin rpy="0 0 0" xyz="0 0 0"/>
      <geometry>
        <box size="0.001 0.001 0.001"/>
      </geometry>
      <material name="Blue"/>
    </visual>
    <inertial>
      <mass value="0"/>
      <inertia ixx="1" ixy="0" ixz="0" iyy="1" iyz="0" izz="0"/>
      <origin xyz="0 0 0"/>
    </inertial>
  </link>
  <joint name="Frontleft_foot_cp_1_joint" type="revolute">
    <axis xyz="0 0 1"/>
    <limit effort="15" lower="0" upper="0" velocity="5"/>
    <origin rpy="0 0 0" xyz="0.08027 0.27372 0"/>
    <parent link="Frontleft_foot_endeffector_link"/>
    <child link="Frontleft_foot_cp_1_link"/>
  </joint>
  <joint name="Frontleft_foot_cp_2_joint" type="revolute">
    <axis xyz="0 0 1"/>
    <limit effort="15" lower="0" upper="0" velocity="5"/>
    <origin rpy="0 0 0" xyz="-0.09166 0.27372 0"/>
    <parent link="Frontleft_foot_endeffector_link"/>
    <child link="Frontleft_foot_cp_2_link"/>
  </joint>
  <joint name="Frontleft_foot_cp_3_joint" type="revolute">
    <axis xyz="0 0 1"/>
    <limit effort="15" lower="0" upper="0" velocity="5"/>
    <origin rpy="0 0 0" xyz="-0.09166 -0.07769 0"/>
    <parent link="Frontleft_foot_endeffector_link"/>
    <child link="Frontleft_foot_cp_3_link"/>
  </joint>
  <joint name="Frontleft_foot_cp_4_joint" type="revolute">
    <axis xyz="0 0 1"/>
    <limit effort="15" lower="0" upper="0" velocity="5"/>
    <origin rpy="0 0 0" xyz="0.08027 -0.07769 0"/>
    <parent link="Frontleft_foot_endeffector_link"/>
    <child link="Frontleft_foot_cp_4_link"/>
  </joint>

   <joint name="BackLeftshoulder_joint" type="revolute">
    <axis xyz="0 0 1"/>
    <limit effort="15" lower="-1.57" upper="1" velocity="5"/>

    <origin rpy="0 0 0" xyz="0 0 0"/>
    <parent link="head_link"/>
    <child link="BackLeftshoulder_link"/>
  </joint>

  <link name="BackLeftshoulder_link"/>
  
  <joint name="BackLeftUpperLimb_z_joint" type="revolute">
    <axis xyz="0 0 1"/>
    <limit effort="15" lower="-1.57" upper="1" velocity="5"/>

    <origin rpy="0 0 0" xyz="-0.1891 0 -0.0795"/>
    <parent link="BackLeftshoulder_link"/>
    <child link="BackLeftUpperLimb_z_link"/>
  </joint>
  <joint name="BackLeftUpperLimb_y_joint" type="revolute">
    <axis xyz="0 1 0"/>
    <limit effort="15" lower="-1.57" upper="0.7" velocity="5"/>
    <origin rpy="0 0 0" xyz="0 0 0"/>
    <parent link="BackLeftUpperLimb_z_link"/>
    <child link="BackLeftUpperLimb_y_link"/>
  </joint>
  <joint name="BackLeftUpperLimb_x_joint" type="revolute">
    <axis xyz="1 0 0"/>
    <limit effort="15" lower="-1.2" upper="1.57" velocity="5"/>
    <origin rpy="0 0 0" xyz="0 0 0"/>
    <parent link="BackLeftUpperLimb_y_link"/>
    <child link="BackLeftUpperLimb_x_link"/>
  </joint>

  <link name="BackLeftUpperLimb_z_link"/>
  <link name="BackLeftUpperLimb_y_link"/>
  <link name="BackLeftUpperLimb_x_link">
    <visual>
      <origin rpy="0 0 0" xyz="0 0 0"/>
      <geometry>
        <mesh filename="../spider/model/mesh/MiddleLeftUpperLimb.obj"/>
      </geometry>
      <material name="Blue"/>
    </visual>
    <collision>
      <origin rpy="0 0 0" xyz="0 0 0"/>
      <geometry>
        <mesh filename="../spider/model/mesh/MiddleLeftUpperLimb.obj"/>
      </geometry>
    </collision>
    <inertial>
      <mass value="11.28066677275"/>
      <inertia ixx="0.258606759375" ixy="0.000002463301455" ixz="0.00032211891975" iyy="0.258311314375" iyz="-0.000065609605275" izz="0.021073428046875"/>
      <origin xyz="-0.00364974 -0.00003172 -0.19576731"/>
    </inertial>
  </link>

  <joint name="BackLeftLimb_joint" type="revolute">
    <axis xyz="0 1 0"/>
    <limit effort="15" lower="-2.4" upper="0" velocity="5"/>
    <origin rpy="0 0 0" xyz="-0.4456 0.0015 0.1781"/>
    <parent link="BackLeftUpperLimb_x_link"/>
    <child link="BackLeftLimb_link"/>
  </joint>

  <link name="BackLeftLimb_link">
    <visual>
      <origin rpy="0 0 0" xyz="0 0 0"/>
      <geometry>
        <mesh filename="../spider/model/mesh/MiddleLeftLimb.obj"/>
      </geometry>
      <material name="Blue"/>
    </visual>
    <collision>
      <origin rpy="0 0 0" xyz="0 0 0"/>
      <geometry>
        <mesh filename="../spider/model/mesh/MiddleLeftLimb.obj"/>
      </geometry>
    </collision>
    <inertial>
      <mass value="8.394054321"/>
      <inertia ixx="0.1879741409375" ixy="0.000000001719205" ixz="-0.00000000509231" iyy="0.1879741525" iyz="-0.00000001780773" izz="0.01166299402353"/>
      <origin xyz="0.0 -0.00029422 -0.20195734"/>
    </inertial>
  </link>

  <joint name="BackLeftLowerLimb_joint" type="revolute">
    <axis xyz="0 1 0"/>
    <limit effort="15" lower="-2.4" upper="0" velocity="5"/>
    <origin rpy="0 0 0" xyz="-0.3928 -0.0167 -0.3044"/>
    <parent link="BackLeftLimb_link"/>
    <child link="BackLeftLowerLimb_link"/>
  </joint>

  <link name="BackLeftLowerLimb_link">
    <visual>
      <origin rpy="0 0 0" xyz="0 0 0"/>
      <geometry>
        <mesh filename="../spider/model/mesh/MiddleLeftLowerLimb.obj"/>
      </geometry>
      <material name="Blue"/>
    </visual>
    <collision>
      <origin rpy="0 0 0" xyz="0 0 0"/>
      <geometry>
        <mesh filename="../spider/model/mesh/MiddleLeftLowerLimb.obj"/>
      </geometry>
    </collision>
    <inertial>
      <mass value="8.394054321"/>
      <inertia ixx="0.1879741409375" ixy="0.000000001719205" ixz="-0.00000000509231" iyy="0.1879741525" iyz="-0.00000001780773" izz="0.01166299402353"/>
      <origin xyz="0.0 -0.00029422 -0.20195734"/>
    </inertial>
  </link>


  <joint name="BackLeftEffector_z_joint" type="revolute">
    <axis xyz="0 0 1"/>
    <limit effort="15" lower="-0.01" upper="0" velocity="5"/>
    <origin rpy="0 0 0" xyz="-0.4343 -0.054 -0.1597"/>
    <parent link="BackLeftLowerLimb_link"/>
    <child link="BackLeftEffector_z_link"/>
  </joint>
  <joint name="BackLeftEffector_y_joint" type="revolute">
    <axis xyz="0 1 0"/>
    <limit effort="15" lower="-0.5" upper="0.5" velocity="5"/>
    <origin rpy="0 0 0" xyz="0 0 0"/>
    <parent link="BackLeftEffector_z_link"/>
    <child link="BackLeftEffector_y_link"/>
  </joint>
  <joint name="BackLeftEffector_x_joint" type="revolute">
    <axis xyz="1 0 0"/>
    <limit effort="15" lower="-0.8" upper="0.6" velocity="5"/>
    <origin rpy="0 0 0" xyz="0 0 0"/>
    <parent link="BackLeftEffector_y_link"/>
    <child link="BackLeftEffector_x_link"/>
  </joint>

  <link name="BackLeftEffector_z_link"/>
  <link name="BackLeftEffector_y_link"/>
  <link name="BackLeftEffector_x_link">
    <visual>
      <origin rpy="0 0 0" xyz="0 0 0"/>
      <geometry>
        <mesh filename="../spider/model/mesh/MiddleLeftEffector.obj"/>
      </geometry>
      <material name="Blue"/>
    </visual>
    <collision>
      <origin rpy="0 0 0" xyz="0 0 0"/>
      <geometry>
        <mesh filename="../spider/model/mesh/MiddleLeftEffector.obj"/>
      </geometry>
    </collision>
    <inertial>
      <mass value="2.24629475115"/>
      <inertia ixx="0.00997119431636" ixy="-0.00032381616821" ixz="0.00003556416949" iyy="0.00325251065432" iyz="0.00137797584221" izz="0.01040399675772"/>
      <origin xyz="-0.00160579 0.04884521 -0.0783361"/>
    </inertial>
  </link>
	
	  
  <joint name="BackLeft_foot_endeffector_joint" type="fixed">
    <axis xyz="0 0 1"/>
    <limit effort="15" lower="-0.001" upper="0.001" velocity="5"/>
    <origin rpy="0 0 0" xyz="-0.024924 -0.097428 0.001788"/>
    <parent link="BackLeftEffector_x_link"/>
    <child link="BackLeft_foot_endeffector_link"/>
  </joint>

  <link name="BackLeft_foot_endeffector_link">
    <visual>
      <origin rpy="0 0 0" xyz="0 0 0"/>
      <geometry>
        <box size="0.001 0.001 0.001"/>
      </geometry>
      <material name="Blue"/>
    </visual>
  </link>  
  
<link name="BackLeft_foot_cp_1_link">
    <visual>
      <origin rpy="0 0 0" xyz="0 0 0"/>
      <geometry>
        <box size="0.001 0.001 0.001"/>
      </geometry>
      <material name="Blue"/>
    </visual>
    <inertial>
      <mass value="0"/>
      <inertia ixx="1" ixy="0" ixz="0" iyy="1" iyz="0" izz="0"/>
      <origin xyz="0 0 0"/>
    </inertial>
  </link>
  <link name="BackLeft_foot_cp_2_link">
    <visual>
      <origin rpy="0 0 0" xyz="0 0 0"/>
      <geometry>
        <box size="0.001 0.001 0.001"/>
      </geometry>
      <material name="Blue"/>
    </visual>
    <inertial>
      <mass value="0"/>
      <inertia ixx="1" ixy="0" ixz="0" iyy="1" iyz="0" izz="0"/>
      <origin xyz="0 0 0"/>
    </inertial>
  </link>
  <link name="BackLeft_foot_cp_3_link">
    <visual>
      <origin rpy="0 0 0" xyz="0 0 0"/>
      <geometry>
        <box size="0.001 0.001 0.001"/>
      </geometry>
      <material name="Blue"/>
    </visual>
    <inertial>
      <mass value="0"/>
      <inertia ixx="1" ixy="0" ixz="0" iyy="1" iyz="0" izz="0"/>
      <origin xyz="0 0 0"/>
    </inertial>
  </link>
  <link name="BackLeft_foot_cp_4_link">
    <visual>
      <origin rpy="0 0 0" xyz="0 0 0"/>
      <geometry>
        <box size="0.001 0.001 0.001"/>
      </geometry>
      <material name="Blue"/>
    </visual>
    <inertial>
      <mass value="0"/>
      <inertia ixx="1" ixy="0" ixz="0" iyy="1" iyz="0" izz="0"/>
      <origin xyz="0 0 0"/>
    </inertial>
  </link>
  <joint name="BackLeft_foot_cp_1_joint" type="revolute">
    <axis xyz="0 0 1"/>
    <limit effort="15" lower="0" upper="0" velocity="5"/>
    <origin rpy="0 0 0" xyz="-0.05 0.02 -0.005"/>
    <parent link="BackLeftEffector_x_link"/>
    <child link="BackLeft_foot_cp_1_link"/>
  </joint>
  <joint name="BackLeft_foot_cp_2_joint" type="revolute">
    <axis xyz="0 0 1"/>
    <limit effort="15" lower="0" upper="0" velocity="5"/>
    <origin rpy="0 0 0" xyz="-0.12 0.02 -0.005"/>
    <parent link="BackLeftEffector_x_link"/>
    <child link="BackLeft_foot_cp_2_link"/>
  </joint>
  <joint name="BackLeft_foot_cp_3_joint" type="revolute">
    <axis xyz="0 0 1"/>
    <limit effort="15" lower="0" upper="0" velocity="5"/>
    <origin rpy="0 0 0" xyz="-0.12 -0.08 -0.005"/>
    <parent link="BackLeftEffector_x_link"/>
    <child link="BackLeft_foot_cp_3_link"/>
  </joint>
  <joint name="BackLeft_foot_cp_4_joint" type="revolute">
    <axis xyz="0 0 1"/>
    <limit effort="15" lower="0" upper="0" velocity="5"/>
    <origin rpy="0 0 0" xyz="-0.05 -0.08 -0.005"/>
    <parent link="BackLeftEffector_x_link"/>
    <child link="BackLeft_foot_cp_4_link"/>
  </joint>

 <joint name="BackRightshoulder_joint" type="revolute">
    <axis xyz="0 0 1"/>
    <limit effort="15" lower="-1.57" upper="1" velocity="5"/>

    <origin rpy="0 0 0" xyz="0 0 0"/>
    <parent link="head_link"/>
    <child link="BackRightshoulder_link"/>
  </joint>

  <link name="BackRightshoulder_link"/>
  
  <joint name="BackRightUpperLimb_z_joint" type="revolute">
    <axis xyz="0 0 1"/>
    <limit effort="15" lower="-1.57" upper="1" velocity="5"/>

    <origin rpy="0 0 0" xyz="-0.1891 0 -0.0795"/>
    <parent link="BackRightshoulder_link"/>
    <child link="BackRightUpperLimb_z_link"/>
  </joint>
  <joint name="BackRightUpperLimb_y_joint" type="revolute">
    <axis xyz="0 1 0"/>
    <limit effort="15" lower="-1.57" upper="0.7" velocity="5"/>
    <origin rpy="0 0 0" xyz="0 0 0"/>
    <parent link="BackRightUpperLimb_z_link"/>
    <child link="BackRightUpperLimb_y_link"/>
  </joint>
  <joint name="BackRightUpperLimb_x_joint" type="revolute">
    <axis xyz="1 0 0"/>
    <limit effort="15" lower="-1.2" upper="1.57" velocity="5"/>
    <origin rpy="0 0 0" xyz="0 0 0"/>
    <parent link="BackRightUpperLimb_y_link"/>
    <child link="BackRightUpperLimb_x_link"/>
  </joint>

  <link name="BackRightUpperLimb_z_link"/>
  <link name="BackRightUpperLimb_y_link"/>
  <link name="BackRightUpperLimb_x_link">
    <visual>
      <origin rpy="0 0 0" xyz="0 0 0"/>
      <geometry>
        <mesh filename="../spider/model/mesh/MiddleLeftUpperLimb.obj"/>
      </geometry>
      <material name="Blue"/>
    </visual>
    <collision>
      <origin rpy="0 0 0" xyz="0 0 0"/>
      <geometry>
        <mesh filename="../spider/model/mesh/MiddleLeftUpperLimb.obj"/>
      </geometry>
    </collision>
    <inertial>
      <mass value="11.28066677275"/>
      <inertia ixx="0.258606759375" ixy="0.000002463301455" ixz="0.00032211891975" iyy="0.258311314375" iyz="-0.000065609605275" izz="0.021073428046875"/>
      <origin xyz="-0.00364974 -0.00003172 -0.19576731"/>
    </inertial>
  </link>

  <joint name="BackRightLimb_joint" type="revolute">
    <axis xyz="0 1 0"/>
    <limit effort="15" lower="-2.4" upper="0" velocity="5"/>
    <origin rpy="0 0 0" xyz="-0.4456 0.0015 0.1781"/>
    <parent link="BackRightUpperLimb_x_link"/>
    <child link="BackRightLimb_link"/>
  </joint>

  <link name="BackRightLimb_link">
    <visual>
      <origin rpy="0 0 0" xyz="0 0 0"/>
      <geometry>
        <mesh filename="../spider/model/mesh/MiddleLeftLimb.obj"/>
      </geometry>
      <material name="Blue"/>
    </visual>
    <collision>
      <origin rpy="0 0 0" xyz="0 0 0"/>
      <geometry>
        <mesh filename="../spider/model/mesh/MiddleLeftLimb.obj"/>
      </geometry>
    </collision>
    <inertial>
      <mass value="8.394054321"/>
      <inertia ixx="0.1879741409375" ixy="0.000000001719205" ixz="-0.00000000509231" iyy="0.1879741525" iyz="-0.00000001780773" izz="0.01166299402353"/>
      <origin xyz="0.0 -0.00029422 -0.20195734"/>
    </inertial>
  </link>

  <joint name="BackRightLowerLimb_joint" type="revolute">
    <axis xyz="0 1 0"/>
    <limit effort="15" lower="-2.4" upper="0" velocity="5"/>
    <origin rpy="0 0 0" xyz="-0.3928 -0.0167 -0.3044"/>
    <parent link="BackRightLimb_link"/>
    <child link="BackRightLowerLimb_link"/>
  </joint>

  <link name="BackRightLowerLimb_link">
    <visual>
      <origin rpy="0 0 0" xyz="0 0 0"/>
      <geometry>
        <mesh filename="../spider/model/mesh/MiddleLeftLowerLimb.obj"/>
      </geometry>
      <material name="Blue"/>
    </visual>
    <collision>
      <origin rpy="0 0 0" xyz="0 0 0"/>
      <geometry>
        <mesh filename="../spider/model/mesh/MiddleLeftLowerLimb.obj"/>
      </geometry>
    </collision>
    <inertial>
      <mass value="8.394054321"/>
      <inertia ixx="0.1879741409375" ixy="0.000000001719205" ixz="-0.00000000509231" iyy="0.1879741525" iyz="-0.00000001780773" izz="0.01166299402353"/>
      <origin xyz="0.0 -0.00029422 -0.20195734"/>
    </inertial>
  </link>


  <joint name="BackRightEffector_z_joint" type="revolute">
    <axis xyz="0 0 1"/>
    <limit effort="15" lower="-0.01" upper="0" velocity="5"/>
    <origin rpy="0 0 0" xyz="-0.4343 -0.054 -0.1597"/>
    <parent link="BackRightLowerLimb_link"/>
    <child link="BackRightEffector_z_link"/>
  </joint>
  <joint name="BackRightEffector_y_joint" type="revolute">
    <axis xyz="0 1 0"/>
    <limit effort="15" lower="-0.5" upper="0.5" velocity="5"/>
    <origin rpy="0 0 0" xyz="0 0 0"/>
    <parent link="BackRightEffector_z_link"/>
    <child link="BackRightEffector_y_link"/>
  </joint>
  <joint name="BackRightEffector_x_joint" type="revolute">
    <axis xyz="1 0 0"/>
    <limit effort="15" lower="-0.8" upper="0.6" velocity="5"/>
    <origin rpy="0 0 0" xyz="0 0 0"/>
    <parent link="BackRightEffector_y_link"/>
    <child link="BackRightEffector_x_link"/>
  </joint>

  <link name="BackRightEffector_z_link"/>
  <link name="BackRightEffector_y_link"/>
  <link name="BackRightEffector_x_link">
    <visual>
      <origin rpy="0 0 0" xyz="0 0 0"/>
      <geometry>
        <mesh filename="../spider/model/mesh/MiddleLeftEffector.obj"/>
      </geometry>
      <material name="Blue"/>
    </visual>
    <collision>
      <origin rpy="0 0 0" xyz="0 0 0"/>
      <geometry>
        <mesh filename="../spider/model/mesh/MiddleLeftEffector.obj"/>
      </geometry>
    </collision>
    <inertial>
      <mass value="2.24629475115"/>
      <inertia ixx="0.00997119431636" ixy="-0.00032381616821" ixz="0.00003556416949" iyy="0.00325251065432" iyz="0.00137797584221" izz="0.01040399675772"/>
      <origin xyz="-0.00160579 0.04884521 -0.0783361"/>
    </inertial>
  </link>
	
	  
  <joint name="BackRight_foot_endeffector_joint" type="fixed">
    <axis xyz="0 0 1"/>
    <limit effort="15" lower="-0.001" upper="0.001" velocity="5"/>
    <origin rpy="0 0 0" xyz="-0.024924 -0.097428 0.001788"/>
    <parent link="BackRightEffector_x_link"/>
    <child link="BackRight_foot_endeffector_link"/>
  </joint>

  <link name="BackRight_foot_endeffector_link">
    <visual>
      <origin rpy="0 0 0" xyz="0 0 0"/>
      <geometry>
        <box size="0.001 0.001 0.001"/>
      </geometry>
      <material name="Blue"/>
    </visual>
  </link>  
  
<link name="BackRight_foot_cp_1_link">
    <visual>
      <origin rpy="0 0 0" xyz="0 0 0"/>
      <geometry>
        <box size="0.001 0.001 0.001"/>
      </geometry>
      <material name="Blue"/>
    </visual>
    <inertial>
      <mass value="0"/>
      <inertia ixx="1" ixy="0" ixz="0" iyy="1" iyz="0" izz="0"/>
      <origin xyz="0 0 0"/>
    </inertial>
  </link>
  <link name="BackRight_foot_cp_2_link">
    <visual>
      <origin rpy="0 0 0" xyz="0 0 0"/>
      <geometry>
        <box size="0.001 0.001 0.001"/>
      </geometry>
      <material name="Blue"/>
    </visual>
    <inertial>
      <mass value="0"/>
      <inertia ixx="1" ixy="0" ixz="0" iyy="1" iyz="0" izz="0"/>
      <origin xyz="0 0 0"/>
    </inertial>
  </link>
  <link name="BackRight_foot_cp_3_link">
    <visual>
      <origin rpy="0 0 0" xyz="0 0 0"/>
      <geometry>
        <box size="0.001 0.001 0.001"/>
      </geometry>
      <material name="Blue"/>
    </visual>
    <inertial>
      <mass value="0"/>
      <inertia ixx="1" ixy="0" ixz="0" iyy="1" iyz="0" izz="0"/>
      <origin xyz="0 0 0"/>
    </inertial>
  </link>
  <link name="BackRight_foot_cp_4_link">
    <visual>
      <origin rpy="0 0 0" xyz="0 0 0"/>
      <geometry>
        <box size="0.001 0.001 0.001"/>
      </geometry>
      <material name="Blue"/>
    </visual>
    <inertial>
      <mass value="0"/>
      <inertia ixx="1" ixy="0" ixz="0" iyy="1" iyz="0" izz="0"/>
      <origin xyz="0 0 0"/>
    </inertial>
  </link>
  <joint name="BackRight_foot_cp_1_joint" type="revolute">
    <axis xyz="0 0 1"/>
    <limit effort="15" lower="0" upper="0" velocity="5"/>
    <origin rpy="0 0 0" xyz="-0.05 0.02 -0.005"/>
    <parent link="BackRightEffector_x_link"/>
    <child link="BackRight_foot_cp_1_link"/>
  </joint>
  <joint name="BackRight_foot_cp_2_joint" type="revolute">
    <axis xyz="0 0 1"/>
    <limit effort="15" lower="0" upper="0" velocity="5"/>
    <origin rpy="0 0 0" xyz="-0.12 0.02 -0.005"/>
    <parent link="BackRightEffector_x_link"/>
    <child link="BackRight_foot_cp_2_link"/>
  </joint>
  <joint name="BackRight_foot_cp_3_joint" type="revolute">
    <axis xyz="0 0 1"/>
    <limit effort="15" lower="0" upper="0" velocity="5"/>
    <origin rpy="0 0 0" xyz="-0.09166 -0.07769 -0.12195"/>
    <parent link="BackRightEffector_x_link"/>
    <child link="BackRight_foot_cp_3_link"/>
  </joint>
  <joint name="BackRight_foot_cp_4_joint" type="revolute">
    <axis xyz="0 0 1"/>
    <limit effort="15" lower="0" upper="0" velocity="5"/>
    <origin rpy="0 0 0" xyz="-0.05 -0.08 -0.005"/>
    <parent link="BackRightEffector_x_link"/>
    <child link="BackRight_foot_cp_4_link"/>
  </joint>
 <joint name="MiddleRightshoulder_joint" type="revolute">
    <axis xyz="0 0 1"/>
    <limit effort="15" lower="-1.57" upper="1" velocity="5"/>

    <origin rpy="0 0 0" xyz="0 0 0"/>
    <parent link="head_link"/>
    <child link="MiddleRightshoulder_link"/>
  </joint>

  <link name="MiddleRightshoulder_link"/>
  
  <joint name="MiddleRightUpperLimb_z_joint" type="revolute">
    <axis xyz="0 0 1"/>
    <limit effort="15" lower="-1.57" upper="1" velocity="5"/>

    <origin rpy="0 0 0" xyz="-0.1891 0 -0.0795"/>
    <parent link="MiddleRightshoulder_link"/>
    <child link="MiddleRightUpperLimb_z_link"/>
  </joint>
  <joint name="MiddleRightUpperLimb_y_joint" type="revolute">
    <axis xyz="0 1 0"/>
    <limit effort="15" lower="-1.57" upper="0.7" velocity="5"/>
    <origin rpy="0 0 0" xyz="0 0 0"/>
    <parent link="MiddleRightUpperLimb_z_link"/>
    <child link="MiddleRightUpperLimb_y_link"/>
  </joint>
  <joint name="MiddleRightUpperLimb_x_joint" type="revolute">
    <axis xyz="1 0 0"/>
    <limit effort="15" lower="-1.2" upper="1.57" velocity="5"/>
    <origin rpy="0 0 0" xyz="0 0 0"/>
    <parent link="MiddleRightUpperLimb_y_link"/>
    <child link="MiddleRightUpperLimb_x_link"/>
  </joint>

  <link name="MiddleRightUpperLimb_z_link"/>
  <link name="MiddleRightUpperLimb_y_link"/>
  <link name="MiddleRightUpperLimb_x_link">
    <visual>
      <origin rpy="0 0 0" xyz="0 0 0"/>
      <geometry>
        <mesh filename="../spider/model/mesh/MiddleLeftUpperLimb.obj"/>
      </geometry>
      <material name="Blue"/>
    </visual>
    <collision>
      <origin rpy="0 0 0" xyz="0 0 0"/>
      <geometry>
        <mesh filename="../spider/model/mesh/MiddleLeftUpperLimb.obj"/>
      </geometry>
    </collision>
    <inertial>
      <mass value="11.28066677275"/>
      <inertia ixx="0.258606759375" ixy="0.000002463301455" ixz="0.00032211891975" iyy="0.258311314375" iyz="-0.000065609605275" izz="0.021073428046875"/>
      <origin xyz="-0.00364974 -0.00003172 -0.19576731"/>
    </inertial>
  </link>

  <joint name="MiddleRightLimb_joint" type="revolute">
    <axis xyz="0 1 0"/>
    <limit effort="15" lower="-2.4" upper="0" velocity="5"/>
    <origin rpy="0 0 0" xyz="-0.4456 0.0015 0.1781"/>
    <parent link="MiddleRightUpperLimb_x_link"/>
    <child link="MiddleRightLimb_link"/>
  </joint>

  <link name="MiddleRightLimb_link">
    <visual>
      <origin rpy="0 0 0" xyz="0 0 0"/>
      <geometry>
        <mesh filename="../spider/model/mesh/MiddleLeftLimb.obj"/>
      </geometry>
      <material name="Blue"/>
    </visual>
    <collision>
      <origin rpy="0 0 0" xyz="0 0 0"/>
      <geometry>
        <mesh filename="../spider/model/mesh/MiddleLeftLimb.obj"/>
      </geometry>
    </collision>
    <inertial>
      <mass value="8.394054321"/>
      <inertia ixx="0.1879741409375" ixy="0.000000001719205" ixz="-0.00000000509231" iyy="0.1879741525" iyz="-0.00000001780773" izz="0.01166299402353"/>
      <origin xyz="0.0 -0.00029422 -0.20195734"/>
    </inertial>
  </link>

  <joint name="MiddleRightLowerLimb_joint" type="revolute">
    <axis xyz="0 1 0"/>
    <limit effort="15" lower="-2.4" upper="0" velocity="5"/>
    <origin rpy="0 0 0" xyz="-0.3928 -0.0167 -0.3044"/>
    <parent link="MiddleRightLimb_link"/>
    <child link="MiddleRightLowerLimb_link"/>
  </joint>

  <link name="MiddleRightLowerLimb_link">
    <visual>
      <origin rpy="0 0 0" xyz="0 0 0"/>
      <geometry>
        <mesh filename="../spider/model/mesh/MiddleLeftLowerLimb.obj"/>
      </geometry>
      <material name="Blue"/>
    </visual>
    <collision>
      <origin rpy="0 0 0" xyz="0 0 0"/>
      <geometry>
        <mesh filename="../spider/model/mesh/MiddleLeftLowerLimb.obj"/>
      </geometry>
    </collision>
    <inertial>
      <mass value="8.394054321"/>
      <inertia ixx="0.1879741409375" ixy="0.000000001719205" ixz="-0.00000000509231" iyy="0.1879741525" iyz="-0.00000001780773" izz="0.01166299402353"/>
      <origin xyz="0.0 -0.00029422 -0.20195734"/>
    </inertial>
  </link>


  <joint name="MiddleRightEffector_z_joint" type="revolute">
    <axis xyz="0 0 1"/>
    <limit effort="15" lower="-0.01" upper="0" velocity="5"/>
    <origin rpy="0 0 0" xyz="-0.4343 -0.054 -0.1597"/>
    <parent link="MiddleRightLowerLimb_link"/>
    <child link="MiddleRightEffector_z_link"/>
  </joint>
  <joint name="MiddleRightEffector_y_joint" type="revolute">
    <axis xyz="0 1 0"/>
    <limit effort="15" lower="-0.5" upper="0.5" velocity="5"/>
    <origin rpy="0 0 0" xyz="0 0 0"/>
    <parent link="MiddleRightEffector_z_link"/>
    <child link="MiddleRightEffector_y_link"/>
  </joint>
  <joint name="MiddleRightEffector_x_joint" type="revolute">
    <axis xyz="1 0 0"/>
    <limit effort="15" lower="-0.8" upper="0.6" velocity="5"/>
    <origin rpy="0 0 0" xyz="0 0 0"/>
    <parent link="MiddleRightEffector_y_link"/>
    <child link="MiddleRightEffector_x_link"/>
  </joint>

  <link name="MiddleRightEffector_z_link"/>
  <link name="MiddleRightEffector_y_link"/>
  <link name="MiddleRightEffector_x_link">
    <visual>
      <origin rpy="0 0 0" xyz="0 0 0"/>
      <geometry>
        <mesh filename="../spider/model/mesh/MiddleLeftEffector.obj"/>
      </geometry>
      <material name="Blue"/>
    </visual>
    <collision>
      <origin rpy="0 0 0" xyz="0 0 0"/>
      <geometry>
        <mesh filename="../spider/model/mesh/MiddleLeftEffector.obj"/>
      </geometry>
    </collision>
    <inertial>
      <mass value="2.24629475115"/>
      <inertia ixx="0.00997119431636" ixy="-0.00032381616821" ixz="0.00003556416949" iyy="0.00325251065432" iyz="0.00137797584221" izz="0.01040399675772"/>
      <origin xyz="-0.00160579 0.04884521 -0.0783361"/>
    </inertial>
  </link>
	
	  
  <joint name="MiddleRight_foot_endeffector_joint" type="fixed">
    <axis xyz="0 0 1"/>
    <limit effort="15" lower="-0.001" upper="0.001" velocity="5"/>
    <origin rpy="0 0 0" xyz="-0.024924 -0.097428 0.001788"/>
    <parent link="MiddleRightEffector_x_link"/>
    <child link="MiddleRight_foot_endeffector_link"/>
  </joint>

  <link name="MiddleRight_foot_endeffector_link">
    <visual>
      <origin rpy="0 0 0" xyz="0 0 0"/>
      <geometry>
        <box size="0.001 0.001 0.001"/>
      </geometry>
      <material name="Blue"/>
    </visual>
  </link>  
  
<link name="MiddleRight_foot_cp_1_link">
    <visual>
      <origin rpy="0 0 0" xyz="0 0 0"/>
      <geometry>
        <box size="0.001 0.001 0.001"/>
      </geometry>
      <material name="Blue"/>
    </visual>
    <inertial>
      <mass value="0"/>
      <inertia ixx="1" ixy="0" ixz="0" iyy="1" iyz="0" izz="0"/>
      <origin xyz="0 0 0"/>
    </inertial>
  </link>
  <link name="MiddleRight_foot_cp_2_link">
    <visual>
      <origin rpy="0 0 0" xyz="0 0 0"/>
      <geometry>
        <box size="0.001 0.001 0.001"/>
      </geometry>
      <material name="Blue"/>
    </visual>
    <inertial>
      <mass value="0"/>
      <inertia ixx="1" ixy="0" ixz="0" iyy="1" iyz="0" izz="0"/>
      <origin xyz="0 0 0"/>
    </inertial>
  </link>
  <link name="MiddleRight_foot_cp_3_link">
    <visual>
      <origin rpy="0 0 0" xyz="0 0 0"/>
      <geometry>
        <box size="0.001 0.001 0.001"/>
      </geometry>
      <material name="Blue"/>
    </visual>
    <inertial>
      <mass value="0"/>
      <inertia ixx="1" ixy="0" ixz="0" iyy="1" iyz="0" izz="0"/>
      <origin xyz="0 0 0"/>
    </inertial>
  </link>
  <link name="MiddleRight_foot_cp_4_link">
    <visual>
      <origin rpy="0 0 0" xyz="0 0 0"/>
      <geometry>
        <box size="0.001 0.001 0.001"/>
      </geometry>
      <material name="Blue"/>
    </visual>
    <inertial>
      <mass value="0"/>
      <inertia ixx="1" ixy="0" ixz="0" iyy="1" iyz="0" izz="0"/>
      <origin xyz="0 0 0"/>
    </inertial>
  </link>
  <joint name="MiddleRight_foot_cp_1_joint" type="revolute">
    <axis xyz="0 0 1"/>
    <limit effort="15" lower="0" upper="0" velocity="5"/>
    <origin rpy="0 0 0" xyz="-0.05 0.02 -0.005"/>
    <parent link="MiddleRightEffector_x_link"/>
    <child link="MiddleRight_foot_cp_1_link"/>
  </joint>
  <joint name="MiddleRight_foot_cp_2_joint" type="revolute">
    <axis xyz="0 0 1"/>
    <limit effort="15" lower="0" upper="0" velocity="5"/>
    <origin rpy="0 0 0" xyz="-0.12 0.02 -0.005"/>
    <parent link="MiddleRightEffector_x_link"/>
    <child link="MiddleRight_foot_cp_2_link"/>
  </joint>
  <joint name="MiddleRight_foot_cp_3_joint" type="revolute">
    <axis xyz="0 0 1"/>
    <limit effort="15" lower="0" upper="0" velocity="5"/>
    <origin rpy="0 0 0" xyz="-0.09166 -0.07769 -0.12195"/>
    <parent link="MiddleRightEffector_x_link"/>
    <child link="MiddleRight_foot_cp_3_link"/>
  </joint>
  <joint name="MiddleRight_foot_cp_4_joint" type="revolute">
    <axis xyz="0 0 1"/>
    <limit effort="15" lower="0" upper="0" velocity="5"/>
    <origin rpy="0 0 0" xyz="-0.05 -0.08 -0.005"/>
    <parent link="MiddleRightEffector_x_link"/>
    <child link="MiddleRight_foot_cp_4_link"/>
  </joint>

 <joint name="FrontRightshoulder_joint" type="revolute">
    <axis xyz="0 0 1"/>
    <limit effort="15" lower="-1.57" upper="1" velocity="5"/>

    <origin rpy="0 0 0" xyz="0 0 0"/>
    <parent link="head_link"/>
    <child link="FrontRightshoulder_link"/>
  </joint>

  <link name="FrontRightshoulder_link"/>
  
  <joint name="FrontRightUpperLimb_z_joint" type="revolute">
    <axis xyz="0 0 1"/>
    <limit effort="15" lower="-1.57" upper="1" velocity="5"/>

    <origin rpy="0 0 0" xyz="-0.1891 0 -0.0795"/>
    <parent link="FrontRightshoulder_link"/>
    <child link="FrontRightUpperLimb_z_link"/>
  </joint>
  <joint name="FrontRightUpperLimb_y_joint" type="revolute">
    <axis xyz="0 1 0"/>
    <limit effort="15" lower="-1.57" upper="0.7" velocity="5"/>
    <origin rpy="0 0 0" xyz="0 0 0"/>
    <parent link="FrontRightUpperLimb_z_link"/>
    <child link="FrontRightUpperLimb_y_link"/>
  </joint>
  <joint name="FrontRightUpperLimb_x_joint" type="revolute">
    <axis xyz="1 0 0"/>
    <limit effort="15" lower="-1.2" upper="1.57" velocity="5"/>
    <origin rpy="0 0 0" xyz="0 0 0"/>
    <parent link="FrontRightUpperLimb_y_link"/>
    <child link="FrontRightUpperLimb_x_link"/>
  </joint>

  <link name="FrontRightUpperLimb_z_link"/>
  <link name="FrontRightUpperLimb_y_link"/>
  <link name="FrontRightUpperLimb_x_link">
    <visual>
      <origin rpy="0 0 0" xyz="0 0 0"/>
      <geometry>
        <mesh filename="../spider/model/mesh/MiddleLeftUpperLimb.obj"/>
      </geometry>
      <material name="Blue"/>
    </visual>
    <collision>
      <origin rpy="0 0 0" xyz="0 0 0"/>
      <geometry>
        <mesh filename="../spider/model/mesh/MiddleLeftUpperLimb.obj"/>
      </geometry>
    </collision>
    <inertial>
      <mass value="11.28066677275"/>
      <inertia ixx="0.258606759375" ixy="0.000002463301455" ixz="0.00032211891975" iyy="0.258311314375" iyz="-0.000065609605275" izz="0.021073428046875"/>
      <origin xyz="-0.00364974 -0.00003172 -0.19576731"/>
    </inertial>
  </link>

  <joint name="FrontRightLimb_joint" type="revolute">
    <axis xyz="0 1 0"/>
    <limit effort="15" lower="-2.4" upper="0" velocity="5"/>
    <origin rpy="0 0 0" xyz="-0.4456 0.0015 0.1781"/>
    <parent link="FrontRightUpperLimb_x_link"/>
    <child link="FrontRightLimb_link"/>
  </joint>

  <link name="FrontRightLimb_link">
    <visual>
      <origin rpy="0 0 0" xyz="0 0 0"/>
      <geometry>
        <mesh filename="../spider/model/mesh/MiddleLeftLimb.obj"/>
      </geometry>
      <material name="Blue"/>
    </visual>
    <collision>
      <origin rpy="0 0 0" xyz="0 0 0"/>
      <geometry>
        <mesh filename="../spider/model/mesh/MiddleLeftLimb.obj"/>
      </geometry>
    </collision>
    <inertial>
      <mass value="8.394054321"/>
      <inertia ixx="0.1879741409375" ixy="0.000000001719205" ixz="-0.00000000509231" iyy="0.1879741525" iyz="-0.00000001780773" izz="0.01166299402353"/>
      <origin xyz="0.0 -0.00029422 -0.20195734"/>
    </inertial>
  </link>

  <joint name="FrontRightLowerLimb_joint" type="revolute">
    <axis xyz="0 1 0"/>
    <limit effort="15" lower="-2.4" upper="0" velocity="5"/>
    <origin rpy="0 0 0" xyz="-0.3928 -0.0167 -0.3044"/>
    <parent link="FrontRightLimb_link"/>
    <child link="FrontRightLowerLimb_link"/>
  </joint>

  <link name="FrontRightLowerLimb_link">
    <visual>
      <origin rpy="0 0 0" xyz="0 0 0"/>
      <geometry>
        <mesh filename="../spider/model/mesh/MiddleLeftLowerLimb.obj"/>
      </geometry>
      <material name="Blue"/>
    </visual>
    <collision>
      <origin rpy="0 0 0" xyz="0 0 0"/>
      <geometry>
        <mesh filename="../spider/model/mesh/MiddleLeftLowerLimb.obj"/>
      </geometry>
    </collision>
    <inertial>
      <mass value="8.394054321"/>
      <inertia ixx="0.1879741409375" ixy="0.000000001719205" ixz="-0.00000000509231" iyy="0.1879741525" iyz="-0.00000001780773" izz="0.01166299402353"/>
      <origin xyz="0.0 -0.00029422 -0.20195734"/>
    </inertial>
  </link>


  <joint name="FrontRightEffector_z_joint" type="revolute">
    <axis xyz="0 0 1"/>
    <limit effort="15" lower="-0.01" upper="0" velocity="5"/>
    <origin rpy="0 0 0" xyz="-0.4343 -0.054 -0.1597"/>
    <parent link="FrontRightLowerLimb_link"/>
    <child link="FrontRightEffector_z_link"/>
  </joint>
  <joint name="FrontRightEffector_y_joint" type="revolute">
    <axis xyz="0 1 0"/>
    <limit effort="15" lower="-0.5" upper="0.5" velocity="5"/>
    <origin rpy="0 0 0" xyz="0 0 0"/>
    <parent link="FrontRightEffector_z_link"/>
    <child link="FrontRightEffector_y_link"/>
  </joint>
  <joint name="FrontRightEffector_x_joint" type="revolute">
    <axis xyz="1 0 0"/>
    <limit effort="15" lower="-0.8" upper="0.6" velocity="5"/>
    <origin rpy="0 0 0" xyz="0 0 0"/>
    <parent link="FrontRightEffector_y_link"/>
    <child link="FrontRightEffector_x_link"/>
  </joint>

  <link name="FrontRightEffector_z_link"/>
  <link name="FrontRightEffector_y_link"/>
  <link name="FrontRightEffector_x_link">
    <visual>
      <origin rpy="0 0 0" xyz="0 0 0"/>
      <geometry>
        <mesh filename="../spider/model/mesh/MiddleLeftEffector.obj"/>
      </geometry>
      <material name="Blue"/>
    </visual>
    <collision>
      <origin rpy="0 0 0" xyz="0 0 0"/>
      <geometry>
        <mesh filename="../spider/model/mesh/MiddleLeftEffector.obj"/>
      </geometry>
    </collision>
    <inertial>
      <mass value="2.24629475115"/>
      <inertia ixx="0.00997119431636" ixy="-0.00032381616821" ixz="0.00003556416949" iyy="0.00325251065432" iyz="0.00137797584221" izz="0.01040399675772"/>
      <origin xyz="-0.00160579 0.04884521 -0.0783361"/>
    </inertial>
  </link>
	
	  
  <joint name="FrontRight_foot_endeffector_joint" type="fixed">
    <axis xyz="0 0 1"/>
    <limit effort="15" lower="-0.001" upper="0.001" velocity="5"/>
    <origin rpy="0 0 0" xyz="-0.024924 -0.097428 0.001788"/>
    <parent link="FrontRightEffector_x_link"/>
    <child link="FrontRight_foot_endeffector_link"/>
  </joint>

  <link name="FrontRight_foot_endeffector_link">
    <visual>
      <origin rpy="0 0 0" xyz="0 0 0"/>
      <geometry>
        <box size="0.001 0.001 0.001"/>
      </geometry>
      <material name="Blue"/>
    </visual>
  </link>  
  
<link name="FrontRight_foot_cp_1_link">
    <visual>
      <origin rpy="0 0 0" xyz="0 0 0"/>
      <geometry>
        <box size="0.001 0.001 0.001"/>
      </geometry>
      <material name="Blue"/>
    </visual>
    <inertial>
      <mass value="0"/>
      <inertia ixx="1" ixy="0" ixz="0" iyy="1" iyz="0" izz="0"/>
      <origin xyz="0 0 0"/>
    </inertial>
  </link>
  <link name="FrontRight_foot_cp_2_link">
    <visual>
      <origin rpy="0 0 0" xyz="0 0 0"/>
      <geometry>
        <box size="0.001 0.001 0.001"/>
      </geometry>
      <material name="Blue"/>
    </visual>
    <inertial>
      <mass value="0"/>
      <inertia ixx="1" ixy="0" ixz="0" iyy="1" iyz="0" izz="0"/>
      <origin xyz="0 0 0"/>
    </inertial>
  </link>
  <link name="FrontRight_foot_cp_3_link">
    <visual>
      <origin rpy="0 0 0" xyz="0 0 0"/>
      <geometry>
        <box size="0.001 0.001 0.001"/>
      </geometry>
      <material name="Blue"/>
    </visual>
    <inertial>
      <mass value="0"/>
      <inertia ixx="1" ixy="0" ixz="0" iyy="1" iyz="0" izz="0"/>
      <origin xyz="0 0 0"/>
    </inertial>
  </link>
  <link name="FrontRight_foot_cp_4_link">
    <visual>
      <origin rpy="0 0 0" xyz="0 0 0"/>
      <geometry>
        <box size="0.001 0.001 0.001"/>
      </geometry>
      <material name="Blue"/>
    </visual>
    <inertial>
      <mass value="0"/>
      <inertia ixx="1" ixy="0" ixz="0" iyy="1" iyz="0" izz="0"/>
      <origin xyz="0 0 0"/>
    </inertial>
  </link>
  <joint name="FrontRight_foot_cp_1_joint" type="revolute">
    <axis xyz="0 0 1"/>
    <limit effort="15" lower="0" upper="0" velocity="5"/>
    <origin rpy="0 0 0" xyz="-0.05 0.02 -0.005"/>
    <parent link="FrontRightEffector_x_link"/>
    <child link="FrontRight_foot_cp_1_link"/>
  </joint>
  <joint name="FrontRight_foot_cp_2_joint" type="revolute">
    <axis xyz="0 0 1"/>
    <limit effort="15" lower="0" upper="0" velocity="5"/>
    <origin rpy="0 0 0" xyz="-0.12 0.02 -0.005"/>
    <parent link="FrontRightEffector_x_link"/>
    <child link="FrontRight_foot_cp_2_link"/>
  </joint>
  <joint name="FrontRight_foot_cp_3_joint" type="revolute">
    <axis xyz="0 0 1"/>
    <limit effort="15" lower="0" upper="0" velocity="5"/>
    <origin rpy="0 0 0" xyz="-0.09166 -0.07769 -0.12195"/>
    <parent link="FrontRightEffector_x_link"/>
    <child link="FrontRight_foot_cp_3_link"/>
  </joint>
  <joint name="FrontRight_foot_cp_4_joint" type="revolute">
    <axis xyz="0 0 1"/>
    <limit effort="15" lower="0" upper="0" velocity="5"/>
    <origin rpy="0 0 0" xyz="-0.05 -0.08 -0.005"/>
    <parent link="FrontRightEffector_x_link"/>
    <child link="FrontRight_foot_cp_4_link"/>
  </joint>


</robot>

