<?xml version="1.0"?>
<robot xmlns:sensor="http://playerstage.sourceforge.net/gazebo/xmlschema/#sensor"
       xmlns:controller="http://playerstage.sourceforge.net/gazebo/xmlschema/#controller"
       xmlns:interface="http://playerstage.sourceforge.net/gazebo/xmlschema/#interface"
       xmlns:xacro="http://playerstage.sourceforge.net/gazebo/xmlschema/#interface"
       name="rocketbox_male" >

  <material name="Blue">
    <color rgba="0.0 0.0 0.8 1.0"/>
  </material>
  <material name="Green">
    <color rgba="0.0 0.8 0.0 1.0"/>
  </material>
  <material name="Grey">
    <color rgba="0.7 0.7 0.7 1.0"/>
  </material>
  <material name="Grey2">
    <color rgba="0.9 0.9 0.9 1.0"/>
  </material>
  <material name="Red">
    <color rgba="0.8 0.0 0.0 1.0"/>
  </material>
  <material name="White">
    <color rgba="1.0 1.0 1.0 1.0"/>
  </material>
  <material name="Black">
    <color rgba="0.1 0.1 0.1 1.0"/>
  </material>
  <material name="LightGrey">
    <color rgba="0.6 0.6 0.6 1.0"/>
  </material>

  <link name="root_link"/>
  <link name="base_prismatic_dummy1">
    <visual>
      <origin rpy="0 0 0" xyz="0 0 0"/>
      <geometry>
        <box size="0.001 0.001 0.001"/>
      </geometry>
      <material name="Blue"/>
    </visual>
  </link>
  <link name="base_prismatic_dummy2">
    <visual>
      <origin rpy="0 0 0" xyz="0 0 0"/>
      <geometry>
        <box size="0.001 0.001 0.001"/>
      </geometry>
      <material name="Blue"/>
    </visual>
  </link>
  <link name="base_prismatic_dummy3">
    <visual>
      <origin rpy="0 0 0" xyz="0 0 0"/>
      <geometry>
        <box size="0.001 0.001 0.001"/>
      </geometry>
      <material name="Blue"/>
    </visual>
  </link>
  <link name="base_revolute_dummy1">
    <visual>
      <origin rpy="0 0 0" xyz="0 0 0"/>
      <geometry>
        <box size="0.001 0.001 0.001"/>
      </geometry>
      <material name="Blue"/>
    </visual>
  </link>
  <link name="base_revolute_dummy2">
    <visual>
      <origin rpy="0 0 0" xyz="0 0 0"/>
      <geometry>
        <box size="0.001 0.001 0.001"/>
      </geometry>
      <material name="Blue"/>
    </visual>
  </link>
  <joint name="base_prismatic_joint_x" type="prismatic">
    <axis xyz="1 0 0"/>
    <limit effort="10000" lower="-5.0" upper="5.0" velocity="0.6"/>
    <safety_controller k_position="100" k_velocity="2000000" soft_lower_limit="-4.9" soft_upper_limit="4.9"/>
    <calibration falling="0.00536"/>
    <dynamics damping="20000.0"/>
    <origin rpy="0 0 0" xyz="0 0 0"/>
    <parent link="root_link"/>
    <child link="base_prismatic_dummy1"/>
  </joint>
  <joint name="base_prismatic_joint_y" type="prismatic">
    <axis xyz="0 1 0"/>
    <limit effort="10000" lower="-5.0" upper="5.0" velocity="0.6"/>
    <safety_controller k_position="100" k_velocity="2000000" soft_lower_limit="-4.9" soft_upper_limit="4.9"/>
    <calibration falling="0.00536"/>
    <dynamics damping="20000.0"/>
    <origin rpy="0 0 0" xyz="0 0 0"/>
    <parent link="base_prismatic_dummy1"/>
    <child link="base_prismatic_dummy2"/>
  </joint>
  <joint name="base_prismatic_joint_z" type="prismatic">
    <axis xyz="0 0 1"/>
    <limit effort="10000" lower="-10.0" upper="10.0" velocity="0.6"/>
    <safety_controller k_position="100" k_velocity="2000000" soft_lower_limit="-10.0" soft_upper_limit="10.0"/>
    <calibration falling="0.00536"/>
    <dynamics damping="20000.0"/>
    <origin rpy="0 0 0" xyz="0 0 0"/>
    <parent link="base_prismatic_dummy2"/>
    <child link="base_prismatic_dummy3"/>
  </joint>
  <joint name="base_revolute_joint_x" type="continuous">
    <axis xyz="1 0 0"/>
    <origin rpy="0 0 0" xyz="0 0 0"/>
    <parent link="base_prismatic_dummy3"/>
    <child link="base_revolute_dummy1"/>
  </joint>
  <joint name="base_revolute_joint_y" type="continuous">
    <axis xyz="0 1 0"/>
    <origin rpy="0 0 0" xyz="0 0 0"/>
    <parent link="base_revolute_dummy1"/>
    <child link="base_revolute_dummy2"/>
  </joint>
  <joint name="base_revolute_joint_z" type="continuous">
    <axis xyz="0 0 1"/>
    <origin rpy="0 0 0" xyz="0 0 0"/>
    <parent link="base_revolute_dummy2"/>
    <child link="pelvis_link"/>
  </joint>  
  <link name="pelvis_link">
    <inertial>
      <mass value="24.9873014159"/>
      <inertia ixx="0.219399825" ixy="0.000000009184695" ixz="0.000000062599005" iyy="0.21939959375" iyz="-0.000000006475555" izz="0.22992248625"/>
      <origin xyz="0 -0.00000001 0.0983925"/>
    </inertial>
  </link>	  
  <joint name="torso_z_joint" type="revolute">
    <axis xyz="0 0 1"/>
    <limit effort="15" lower="-0.7" upper="0.7" velocity="5"/>
    <origin rpy="0 0 0" xyz="0 0 0"/>
    <parent link="pelvis_link"/>
    <child link="torso_z_link"/>
  </joint>
  <joint name="torso_y_joint" type="revolute">
    <axis xyz="0 1 0"/>
    <limit effort="15" lower="-0.3" upper="0.3" velocity="5"/>
    <origin rpy="0 0 0" xyz="0 0 0"/>
    <parent link="torso_z_link"/>
    <child link="torso_y_link"/>
  </joint>
  <joint name="torso_x_joint" type="revolute">
    <axis xyz="1 0 0"/>
    <limit effort="15" lower="-1.0" upper="0" velocity="5"/>
    <origin rpy="0 0 0" xyz="0 0 0"/>
    <parent link="torso_y_link"/>
    <child link="torso_x_link"/>
  </joint>  

  <link name="torso_z_link"/>
  <link name="torso_y_link"/>
  <link name="torso_x_link">
    <visual>
      <origin rpy="0 0 0" xyz="0 0 0"/>
      <geometry>
        <mesh filename="../spider/model/mesh/Root.obj"/>
      </geometry>
      <material name="Blue"/>
    </visual>
    <collision>
      <origin rpy="0 0 0" xyz="0 0 0"/>
      <geometry>
        <mesh filename="../spider/model/mesh/Root.obj"/>
      </geometry>
    </collision>
    <inertial>
      <mass value="54.1902903318"/>
      <inertia ixx="1.0895931125" ixy="0.000001152997515" ixz="-0.000000460619845" iyy="1.4490895525" iyz="0.000000968452985" izz="0.679463005"/>
      <origin xyz="0 -0.00000025 0.22608234"/>
    </inertial>
  </link>  
  
  <joint name="head_joint" type="revolute">
    <axis xyz="0 0 1"/>
    <limit effort="15" lower="-1.2" upper="1.2" velocity="5"/>
    <origin rpy="0 0 0" xyz="0 0.4982 0"/>
    <parent link="torso_x_link"/>
    <child link="head_link"/>
  </joint>

  <link name="head_link"/>
  
  <joint name="FrontLeftUpperLimb_z_joint" type="revolute">
    <axis xyz="0 0 1"/>
    <limit effort="15" lower="-1.57" upper="1" velocity="5"/>

    <origin rpy="0 0 0" xyz="-0.1619 0.1824 -0.0689"/>
    <parent link="head_link"/>
    <child link="FrontLeftUpperLimb_z_link"/>
  </joint>
  <joint name="FrontLeftUpperLimb_y_joint" type="revolute">
    <axis xyz="0 1 0"/>
    <limit effort="15" lower="-1.57" upper="0.7" velocity="5"/>
    <origin rpy="0 0 0" xyz="0 0 0"/>
    <parent link="FrontLeftUpperLimb_z_link"/>
    <child link="FrontLeftUpperLimb_y_link"/>
  </joint>
  <joint name="FrontLeftUpperLimb_x_joint" type="revolute">
    <axis xyz="1 0 0"/>
    <limit effort="15" lower="-1.2" upper="1.57" velocity="5"/>
    <origin rpy="0 0 0" xyz="0 0 0"/>
    <parent link="FrontLeftUpperLimb_y_link"/>
    <child link="FrontLeftUpperLimb_x_link"/>
  </joint>

  <link name="FrontLeftUpperLimb_z_link"/>
  <link name="FrontLeftUpperLimb_y_link"/>
  <link name="FrontLeftUpperLimb_x_link">
    <visual>
      <origin rpy="0 0 0" xyz="0 0 0"/>
      <geometry>
        <mesh filename="../spider/model/mesh/FrontLeftUpperLimb.obj"/>
      </geometry>
      <material name="Blue"/>
    </visual>
    <collision>
      <origin rpy="0 0 0" xyz="0 0 0"/>
      <geometry>
        <mesh filename="../spider/model/mesh/FrontLeftUpperLimb.obj"/>
      </geometry>
    </collision>
    <inertial>
      <mass value="11.28066677275"/>
      <inertia ixx="0.258606759375" ixy="0.000002463301455" ixz="0.00032211891975" iyy="0.258311314375" iyz="-0.000065609605275" izz="0.021073428046875"/>
      <origin xyz="-0.00364974 -0.00003172 -0.19576731"/>
    </inertial>
  </link>

  <joint name="FrontLeftLimb_joint" type="revolute">
    <axis xyz="1 0 0"/>
    <limit effort="15" lower="-2.4" upper="0" velocity="5"/>
    <origin rpy="0 0 0" xyz="-0.3344 0.3178 0.1886"/>
    <parent link="FrontLeftUpperLimb_x_link"/>
    <child link="FrontLeftLimb_link"/>
  </joint>

  <link name="FrontLeftLimb_link">
    <visual>
      <origin rpy="0 0 0" xyz="0 0 0"/>
      <geometry>
        <mesh filename="../spider/model/mesh/FrontLeftLimb.obj"/>
      </geometry>
      <material name="Blue"/>
    </visual>
    <collision>
      <origin rpy="0 0 0" xyz="0 0 0"/>
      <geometry>
        <mesh filename="../spider/model/mesh/FrontLeftLimb.obj"/>
      </geometry>
    </collision>
    <inertial>
      <mass value="8.394054321"/>
      <inertia ixx="0.1879741409375" ixy="0.000000001719205" ixz="-0.00000000509231" iyy="0.1879741525" iyz="-0.00000001780773" izz="0.01166299402353"/>
      <origin xyz="0.0 -0.00029422 -0.20195734"/>
    </inertial>
  </link>

  <joint name="FrontLeftLowerLimb_joint" type="revolute">
    <axis xyz="1 0 0"/>
    <limit effort="15" lower="-2.4" upper="0" velocity="5"/>
    <origin rpy="0 0 0" xyz="-0.2936 0.2729 -0.2964"/>
    <parent link="FrontLeftLimb_link"/>
    <child link="FrontLeftLowerLimb_link"/>
  </joint>

  <link name="FrontLeftLowerLimb_link">
    <visual>
      <origin rpy="0 0 0" xyz="0 0 0"/>
      <geometry>
        <mesh filename="../spider/model/mesh/FrontLeftLowerLimb.obj"/>
      </geometry>
      <material name="Blue"/>
    </visual>
    <collision>
      <origin rpy="0 0 0" xyz="0 0 0"/>
      <geometry>
        <mesh filename="../spider/model/mesh/FrontLeftLowerLimb.obj"/>
      </geometry>
    </collision>
    <inertial>
      <mass value="8.394054321"/>
      <inertia ixx="0.1879741409375" ixy="0.000000001719205" ixz="-0.00000000509231" iyy="0.1879741525" iyz="-0.00000001780773" izz="0.01166299402353"/>
      <origin xyz="0.0 -0.00029422 -0.20195734"/>
    </inertial>
  </link>


  <joint name="FrontLeftEffector_z_joint" type="revolute">
    <axis xyz="0 0 1"/>
    <limit effort="15" lower="-0.01" upper="0" velocity="5"/>
    <origin rpy="0 0 0" xyz="-0.3452 0.2005 -0.166"/>
    <parent link="FrontLeftLowerLimb_link"/>
    <child link="FrontLeftEffector_z_link"/>
  </joint>
  <joint name="FrontLeftEffector_y_joint" type="revolute">
    <axis xyz="0 1 0"/>
    <limit effort="15" lower="-0.5" upper="0.5" velocity="5"/>
    <origin rpy="0 0 0" xyz="0 0 0"/>
    <parent link="FrontLeftEffector_z_link"/>
    <child link="FrontLeftEffector_y_link"/>
  </joint>
  <joint name="FrontLeftEffector_x_joint" type="revolute">
    <axis xyz="1 0 0"/>
    <limit effort="15" lower="-0.8" upper="0.6" velocity="5"/>
    <origin rpy="0 0 0" xyz="0 0 0"/>
    <parent link="FrontLeftEffector_y_link"/>
    <child link="FrontLeftEffector_x_link"/>
  </joint>

  <link name="FrontLeftEffector_z_link"/>
  <link name="FrontLeftEffector_y_link"/>
  <link name="FrontLeftEffector_x_link">
    <visual>
      <origin rpy="0 0 0" xyz="0 0 0"/>
      <geometry>
        <mesh filename="../spider/model/mesh/FrontLeftEffector.obj"/>
      </geometry>
      <material name="Blue"/>
    </visual>
    <collision>
      <origin rpy="0 0 0" xyz="0 0 0"/>
      <geometry>
        <mesh filename="../spider/model/mesh/FrontLeftEffector.obj"/>
      </geometry>
    </collision>
    <inertial>
      <mass value="2.24629475115"/>
      <inertia ixx="0.00997119431636" ixy="-0.00032381616821" ixz="0.00003556416949" iyy="0.00325251065432" iyz="0.00137797584221" izz="0.01040399675772"/>
      <origin xyz="-0.00160579 0.04884521 -0.0783361"/>
    </inertial>
  </link>
	
	  
  <joint name="left_foot_endeffector_joint" type="fixed">
    <axis xyz="0 0 1"/>
    <limit effort="15" lower="-0.001" upper="0.001" velocity="5"/>
    <origin rpy="0 0 0" xyz="-0.024924 -0.097428 0.001788"/>
    <parent link="FrontLeftEffector_x_link"/>
    <child link="left_foot_endeffector_link"/>
  </joint>

  <link name="left_foot_endeffector_link">
    <visual>
      <origin rpy="0 0 0" xyz="0 0 0"/>
      <geometry>
        <box size="0.001 0.001 0.001"/>
      </geometry>
      <material name="Blue"/>
    </visual>
  </link>  
  
<link name="left_foot_cp_1_link">
    <visual>
      <origin rpy="0 0 0" xyz="0 0 0"/>
      <geometry>
        <box size="0.001 0.001 0.001"/>
      </geometry>
      <material name="Blue"/>
    </visual>
    <inertial>
      <mass value="0"/>
      <inertia ixx="1" ixy="0" ixz="0" iyy="1" iyz="0" izz="0"/>
      <origin xyz="0 0 0"/>
    </inertial>
  </link>
  <link name="left_foot_cp_2_link">
    <visual>
      <origin rpy="0 0 0" xyz="0 0 0"/>
      <geometry>
        <box size="0.001 0.001 0.001"/>
      </geometry>
      <material name="Blue"/>
    </visual>
    <inertial>
      <mass value="0"/>
      <inertia ixx="1" ixy="0" ixz="0" iyy="1" iyz="0" izz="0"/>
      <origin xyz="0 0 0"/>
    </inertial>
  </link>
  <link name="left_foot_cp_3_link">
    <visual>
      <origin rpy="0 0 0" xyz="0 0 0"/>
      <geometry>
        <box size="0.001 0.001 0.001"/>
      </geometry>
      <material name="Blue"/>
    </visual>
    <inertial>
      <mass value="0"/>
      <inertia ixx="1" ixy="0" ixz="0" iyy="1" iyz="0" izz="0"/>
      <origin xyz="0 0 0"/>
    </inertial>
  </link>
  <link name="left_foot_cp_4_link">
    <visual>
      <origin rpy="0 0 0" xyz="0 0 0"/>
      <geometry>
        <box size="0.001 0.001 0.001"/>
      </geometry>
      <material name="Blue"/>
    </visual>
    <inertial>
      <mass value="0"/>
      <inertia ixx="1" ixy="0" ixz="0" iyy="1" iyz="0" izz="0"/>
      <origin xyz="0 0 0"/>
    </inertial>
  </link>
  <joint name="left_foot_cp_1_joint" type="revolute">
    <axis xyz="0 0 1"/>
    <limit effort="15" lower="0" upper="0" velocity="5"/>
    <origin rpy="0 0 0" xyz="0.08027 0.27372 -0.12195"/>
    <parent link="FrontLeftEffector_x_link"/>
    <child link="left_foot_cp_1_link"/>
  </joint>
  <joint name="left_foot_cp_2_joint" type="revolute">
    <axis xyz="0 0 1"/>
    <limit effort="15" lower="0" upper="0" velocity="5"/>
    <origin rpy="0 0 0" xyz="-0.09166 0.27372 -0.12195"/>
    <parent link="FrontLeftEffector_x_link"/>
    <child link="left_foot_cp_2_link"/>
  </joint>
  <joint name="left_foot_cp_3_joint" type="revolute">
    <axis xyz="0 0 1"/>
    <limit effort="15" lower="0" upper="0" velocity="5"/>
    <origin rpy="0 0 0" xyz="-0.09166 -0.07769 -0.12195"/>
    <parent link="FrontLeftEffector_x_link"/>
    <child link="left_foot_cp_3_link"/>
  </joint>
  <joint name="left_foot_cp_4_joint" type="revolute">
    <axis xyz="0 0 1"/>
    <limit effort="15" lower="0" upper="0" velocity="5"/>
    <origin rpy="0 0 0" xyz="0.08027 -0.07769 -0.12195"/>
    <parent link="FrontLeftEffector_x_link"/>
    <child link="left_foot_cp_4_link"/>
  </joint>

</robot>

